<?xml version="1.0"?>
<!-- PAROL6完整版：原始场景 + 固定夹爪 -->
<mujoco model="parol6_full">
    <size memory="500M"/>
    <compiler angle="radian" autolimits="true" eulerseq="xyz"/>
    <option integrator="RK4" noslip_iterations="20"/>
    
    <default>
        <joint armature="0.1" damping="0.1"/>
        <default class="visual_only">
            <geom type="mesh" contype="0" conaffinity="0" group="2"/>
        </default>
        <default class="visual_collision">
            <geom type="mesh" solimp=".9 .99 .001" solref=".015 1" group="2"/>
        </default>
    </default>
    
    <!-- 场景：天空、地面、桌子、物体 -->
    <include file="../asset/tabletop/object/floor_isaac_style.xml"/>
    <include file="../asset/tabletop/object/object_table.xml"/>
    <include file="../asset/objaverse/mug_5/model_new.xml"/>
    <include file="../asset/objaverse/plate_11/model_new.xml"/>
    <include file="../asset/objaverse/mug_6/model_new.xml"/>
    
    <!-- 机械臂网格 -->
    <asset>
        <mesh name="base_link" file="01-Parol6/meshes/base_link.STL" scale="0.001 0.001 0.001"/>
        <mesh name="l1" file="01-Parol6/meshes/L1.STL" scale="0.001 0.001 0.001"/>
        <mesh name="l2" file="01-Parol6/meshes/L2.STL" scale="0.001 0.001 0.001"/>
        <mesh name="l3" file="01-Parol6/meshes/L3.STL" scale="0.001 0.001 0.001"/>
        <mesh name="l4" file="01-Parol6/meshes/L4.STL" scale="0.001 0.001 0.001"/>
        <mesh name="l5" file="01-Parol6/meshes/L5.STL" scale="0.001 0.001 0.001"/>
        <mesh name="l6" file="01-Parol6/meshes/L6.STL" scale="0.001 0.001 0.001"/>
    </asset>
    
    <!-- PAROL6机械臂 -->
    <worldbody>
        <body name="base_link" pos="0.2 0 0.8">
            <inertial pos="-0.0275 -0.0014 0.0312" mass="0.8127" diaginertia="0.001479 0.001107 0.001066"/>
            <geom type="mesh" mesh="base_link" rgba="0.75 0.75 0.75 1"/>
            
            <body name="L1" pos="0.0000 0.0000 0.0000" quat="1.0000 0.0000 0.0000 0.0000">
                <inertial pos="0.0052 0.0290 0.0993" mass="0.6448" diaginertia="0.001295 0.001094 0.000570"/>
                <joint name="L1" type="hinge" axis="0 0 1" range="-1.70 1.70" damping="1.0"/>
                <geom type="mesh" mesh="l1" rgba="0.75 0.75 0.75 1"/>
                
                <body name="L2" pos="0.0234 0.0000 0.1105" quat="0.7071 -0.7071 0.0000 0.0000">
                    <inertial pos="-0.0094 -0.0784 0.0369" mass="0.5123" diaginertia="0.001322 0.001234 0.000205"/>
                    <joint name="L2" type="hinge" axis="0 0 1" range="-0.98 1.00" damping="1.0"/>
                    <geom type="mesh" mesh="l2" rgba="0.75 0.75 0.75 1"/>
                    
                    <body name="L3" pos="0.0000 -0.1800 0.0000" quat="0.0000 0.7071 -0.7071 0.0000">
                        <inertial pos="0.0156 -0.0191 -0.0015" mass="0.5510" diaginertia="0.000816 0.000578 0.000567"/>
                        <joint name="L3" type="hinge" axis="0 0 -1" range="-2.00 1.30" damping="1.0"/>
                        <geom type="mesh" mesh="l3" rgba="0.75 0.75 0.75 1"/>
                        
                        <body name="L4" pos="0.0435 0.0000 0.0000" quat="0.0000 0.0000 0.7071 0.7071">
                            <inertial pos="0.0009 -0.0090 -0.0925" mass="0.3935" diaginertia="0.000372 0.000332 0.000251"/>
                            <joint name="L4" type="hinge" axis="0 0 -1" range="-2.00 2.00" damping="1.0"/>
                            <geom type="mesh" mesh="l4" rgba="0.75 0.75 0.75 1"/>
                            
                            <body name="L5" pos="0.0000 0.0000 -0.1764" quat="0.7071 -0.7071 0.0000 0.0000">
                                <inertial pos="0.0000 -0.0062 -0.0010" mass="0.1852" diaginertia="0.000111 0.000109 0.000084"/>
                                <joint name="L5" type="hinge" axis="0 0 -1" range="-2.10 2.10" damping="1.0"/>
                                <geom type="mesh" mesh="l5" rgba="0.75 0.75 0.75 1"/>
                                
                                <!-- L6包含夹爪（固定） -->
                                <body name="L6" pos="0.0000 0.0000 0.0000" quat="0.7071 0.7071 0.0000 0.0000">
                                    <inertial pos="0.0063 -0.0005 -0.0654" mass="0.1703" diaginertia="0.000123 0.000118 0.000114"/>
                                    <joint name="L6" type="hinge" axis="0 0 -1" limited="false" damping="0.3"/>
                                    <geom type="mesh" mesh="l6" rgba="0.75 0.75 0.75 1"/>
                                    
                                    <!-- 末端site和摄像头 -->
                                    <site name="end_effector" pos="0 0 -0.10" size="0.01"/>
                                    <camera name="gripper_cam" pos="0 -0.1 -0.08" xyaxes="0 0 1 -1 0 0" mode="fixed" fovy="60"/>
                                </body>
                            </body>
                        </body>
                    </body>
                </body>
            </body>
        </body>
    </worldbody>
    
    <!-- 执行器 -->
    <actuator>
        <position name="L1_motor" joint="L1" kp="100" ctrlrange="-1.70 1.70"/>
        <position name="L2_motor" joint="L2" kp="100" ctrlrange="-0.98 1.00"/>
        <position name="L3_motor" joint="L3" kp="100" ctrlrange="-2.00 1.30"/>
        <position name="L4_motor" joint="L4" kp="80" ctrlrange="-2.00 2.00"/>
        <position name="L5_motor" joint="L5" kp="80" ctrlrange="-2.10 2.10"/>
        <position name="L6_motor" joint="L6" kp="50" ctrlrange="-3.14 3.14"/>
    </actuator>
    
    <!-- 传感器 -->
    <sensor>
        <jointpos name="L1_pos" joint="L1"/>
        <jointpos name="L2_pos" joint="L2"/>
        <jointpos name="L3_pos" joint="L3"/>
        <jointpos name="L4_pos" joint="L4"/>
        <jointpos name="L5_pos" joint="L5"/>
        <jointpos name="L6_pos" joint="L6"/>
        <jointvel name="L1_vel" joint="L1"/>
        <jointvel name="L2_vel" joint="L2"/>
        <jointvel name="L3_vel" joint="L3"/>
        <jointvel name="L4_vel" joint="L4"/>
        <jointvel name="L5_vel" joint="L5"/>
        <jointvel name="L6_vel" joint="L6"/>
    </sensor>
</mujoco>
